Workbook

Sheet Assumptions
C1: StratiqAI | 5-Year DCF Model
A2: Assumptions & Key Inputs
A5: PROPERTY ASSUMPTIONS
B6: Property Name
B7: Property Type
B8: Location
B9: Net Rentable Area (SF)
B10: Purchase Price
B11: Price per SF
B12: Closing Costs (% of Price)
B13: Capital Improvements (Year 0)
A15: REVENUE ASSUMPTIONS
B16: Base Rent (Year 1, $/SF)
B17: Annual Rent Escalation
B18: Occupancy Rate (Year 1)
B19: Occupancy Stabilization
B20: Other Income (% of EGI)
A22: OPERATING EXPENSE ASSUMPTIONS
B23: Operating Expenses (Year 1, $/SF)
B24: OpEx Annual Escalation
B25: Management Fee (% of EGI)
B26: Replacement Reserves ($/SF)
B27: Leasing Commissions (% on new)
B28: Tenant Improvements ($/SF)
A30: FINANCING ASSUMPTIONS
B31: Loan-to-Value (LTV)
B32: Loan Amount
B33: Interest Rate
B34: Loan Term
B35: Amortization Period
B36: Annual Debt Service
B37: Equity Required
A39: EXIT / REVERSION ASSUMPTIONS
B40: Exit Cap Rate
B41: Selling Costs (% of Sale Price)
B42: Year 6 NOI (Exit Year)
A44: TAX ASSUMPTIONS
B45: Ordinary Income Tax Rate
B46: Capital Gains Tax Rate
B47: Depreciation Recapture Rate
...

Sheet Before-Tax DCF
C1: StratiqAI | 5-Year DCF Model
A2: Before-Tax Cash Flow Analysis
B5: ($) | C5: Year 0 | D5: Year 1 | E5: Year 2 | F5: Year 3 | G5: Year 4 | H5: Year 5
A7: REVENUE
B8: Gross Potential Rent | D8: =Assumptions!C9*Assumptions!C16 -> 0 | E8: =D8*(1+Assumptions!C17) -> 0 | F8: =E8*(1+Assumptions!C17) -> 0 | G8: =F8*(1+Assumptions!C17) -> 0 | H8: =G8*(1+Assumptions!C17) -> 0
B9: Less: Vacancy Loss | D9: =-D8*(1-Assumptions!C18) -> 0 | E9: =-E8*(1-0.935) -> 0 | F9: =-F8*(1-Assumptions!C19) -> 0 | G9: =-G8*(1-Assumptions!C19) -> 0 | H9: =-H8*(1-Assumptions!C19) -> 0
B10: Effective Rental Income | D10: =D8+D9 -> 0 | E10: =E8+E9 -> 0 | F10: =F8+F9 -> 0 | G10: =G8+G9 -> 0 | H10: =H8+H9 -> 0
B11: Plus: Other Income | D11: =D10*Assumptions!C20 -> 0 | E11: =E10*Assumptions!C20 -> 0 | F11: =F10*Assumptions!C20 -> 0 | G11: =G10*Assumptions!C20 -> 0 | H11: =H10*Assumptions!C20 -> 0
B12: Effective Gross Income (EGI) | D12: =D10+D11 -> 0 | E12: =E10+E11 -> 0 | F12: =F10+F11 -> 0 | G12: =G10+G11 -> 0 | H12: =H10+H11 -> 0
A14: OPERATING EXPENSES
B15: Operating Expenses | D15: =-Assumptions!C9*Assumptions!C23 -> 0 | E15: =D15*(1+Assumptions!C24) -> 0 | F15: =E15*(1+Assumptions!C24) -> 0 | G15: =F15*(1+Assumptions!C24) -> 0 | H15: =G15*(1+Assumptions!C24) -> 0
B16: Management Fee | D16: =-D12*Assumptions!C25 -> 0 | E16: =-E12*Assumptions!C25 -> 0 | F16: =-F12*Assumptions!C25 -> 0 | G16: =-G12*Assumptions!C25 -> 0 | H16: =-H12*Assumptions!C25 -> 0
B17: Replacement Reserves | D17: =-Assumptions!C9*Assumptions!C26 -> 0 | E17: =D17 -> 0 | F17: =E17 -> 0 | G17: =F17 -> 0 | H17: =G17 -> 0
B18: Total Operating Expenses | D18: =D15+D16+D17 -> 0 | E18: =E15+E16+E17 -> 0 | F18: =F15+F16+F17 -> 0 | G18: =G15+G16+G17 -> 0 | H18: =H15+H16+H17 -> 0
A20: NET OPERATING INCOME (NOI)
B21: Net Operating Income | D21: =D12+D18 -> 0 | E21: =E12+E18 -> 0 | F21: =F12+F18 -> 0 | G21: =G12+G18 -> 0 | H21: =H12+H18 -> 0
A23: UNLEVERED BEFORE-TAX CASH FLOW
B24: Acquisition Cost | C24: =-(Assumptions!C10*(1+Assumptions!C12)+Assumptions!C13) -> 0
B25: Net Operating Income | D25: =D21 -> 0 | E25: =E21 -> 0 | F25: =F21 -> 0 | G25: =G21 -> 0 | H25: =H21 -> 0
B26: Net Sale Proceeds (Reversion) | H26: =(Assumptions!C42/Assumptions!C40)*(1-Assumptions!C41) -> #DIV/0!
B27: Unlevered Before-Tax CF | C27: =C24 -> 0 | D27: =D25 -> 0 | E27: =E25 -> 0 | F27: =F25 -> 0 | G27: =G25 -> 0 | H27: =H25+H26 -> #DIV/0!
A29: UNLEVERED RETURN METRICS
B30: Unlevered IRR | C30: =IRR(C27:H27) -> #DIV/0!
B31: Unlevered NPV | C31: =NPV(Assumptions!C52,D27:H27)+C27 -> #DIV/0!
B32: Equity Multiple | C32: =(SUM(D27:H27))/-C27 -> #DIV/0!
A35: LEVERED BEFORE-TAX CASH FLOW
B36: Equity Investment | C36: =-Assumptions!C37 -> 0
B37: Net Operating Income | D37: =D21 -> 0 | E37: =E21 -> 0 | F37: =F21 -> 0 | G37: =G21 -> 0 | H37: =H21 -> 0
B38: Less: Debt Service | D38: =-Assumptions!C36 -> 0 | E38: =D38 -> 0 | F38: =E38 -> 0 | G38: =F38 -> 0 | H38: =G38 -> 0
B39: Before-Tax Cash Flow (Ops) | D39: =D37+D38 -> 0 | E39: =E37+E38 -> 0 | F39: =F37+F38 -> 0 | G39: =G37+G38 -> 0 | H39: =H37+H38 -> 0
B40: Net Sale Proceeds (after payoff) | H40: =H26+FV(Assumptions!C33/12,5*12,-Assumptions!C36/12,Assumptions!C32) -> #DIV/0!
B41: Levered Before-Tax CF | C41: =C36 -> 0 | D41: =D39 -> 0 | E41: =E39 -> 0 | F41: =F39 -> 0 | G41: =G39 -> 0 | H41: =H39+H40 -> #DIV/0!
A43: LEVERED RETURN METRICS
B44: Levered IRR | C44: =IRR(C41:H41) -> #DIV/0!
B45: Levered NPV | C45: =NPV(Assumptions!C53,D41:H41)+C41 -> #DIV/0!
B46: Equity Multiple | C46: =(SUM(D41:H41))/-C41 -> #DIV/0!
B47: Cash-on-Cash Return (Year 1) | C47: =D39/-C36 -> #DIV/0!

Sheet After-Tax DCF
C1: StratiqAI | 5-Year DCF Model
A2: After-Tax Cash Flow Analysis
B5: ($) | C5: Year 0 | D5: Year 1 | E5: Year 2 | F5: Year 3 | G5: Year 4 | H5: Year 5
A7: DEPRECIATION SCHEDULE
B8: Depreciable Basis | C8: =Assumptions!C10*Assumptions!C48+Assumptions!C13 -> 0
B9: Annual Depreciation | D9: =-C8/Assumptions!C49 -> #DIV/0! | E9: =D9 -> #DIV/0! | F9: =E9 -> #DIV/0! | G9: =F9 -> #DIV/0! | H9: =G9 -> #DIV/0!
B10: Accumulated Depreciation | D10: =D9 -> #DIV/0! | E10: =D10+E9 -> #DIV/0! | F10: =E10+F9 -> #DIV/0! | G10: =F10+G9 -> #DIV/0! | H10: =G10+H9 -> #DIV/0!
B11: Adjusted Basis at Sale (Year 5) | H11: =(Assumptions!C10+Assumptions!C13)+H10 -> #DIV/0!
A13: TAX ON OPERATING INCOME
B14: Net Operating Income | D14: ='Before-Tax DCF'!D21 -> 0 | E14: ='Before-Tax DCF'!E21 -> 0 | F14: ='Before-Tax DCF'!F21 -> 0 | G14: ='Before-Tax DCF'!G21 -> 0 | H14: ='Before-Tax DCF'!H21 -> 0
B15: Less: Interest Expense | D15: =IPMT(Assumptions!C33/12,1,Assumptions!C35*12,-Assumptions!C32)*12 -> #VALUE! | E15: =IPMT(Assumptions!C33/12,13,Assumptions!C35*12,-Assumptions!C32)*12 -> #VALUE! | F15: =IPMT(Assumptions!C33/12,25,Assumptions!C35*12,-Assumptions!C32)*12 -> #VALUE! | G15: =IPMT(Assumptions!C33/12,37,Assumptions!C35*12,-Assumptions!C32)*12 -> #VALUE! | H15: =IPMT(Assumptions!C33/12,49,Assumptions!C35*12,-Assumptions!C32)*12 -> #VALUE!
B16: Less: Depreciation | D16: =D9 -> #DIV/0! | E16: =E9 -> #DIV/0! | F16: =F9 -> #DIV/0! | G16: =G9 -> #DIV/0! | H16: =H9 -> #DIV/0!
B17: Taxable Income (Operations) | D17: =D14+D15+D16 -> #VALUE! | E17: =E14+E15+E16 -> #VALUE! | F17: =F14+F15+F16 -> #VALUE! | G17: =G14+G15+G16 -> #VALUE! | H17: =H14+H15+H16 -> #VALUE!
B18: Tax on Operations | D18: =-MAX(D17,0)*Assumptions!C45 -> #VALUE! | E18: =-MAX(E17,0)*Assumptions!C45 -> #VALUE! | F18: =-MAX(F17,0)*Assumptions!C45 -> #VALUE! | G18: =-MAX(G17,0)*Assumptions!C45 -> #VALUE! | H18: =-MAX(H17,0)*Assumptions!C45 -> #VALUE!
A20: TAX ON SALE (YEAR 5)
B21: Gross Sale Price | H21: =Assumptions!C42/Assumptions!C40 -> #DIV/0!
B22: Less: Adjusted Basis | H22: =-H11 -> #DIV/0!
B23: Less: Selling Costs | H23: =-H21*Assumptions!C41 -> #DIV/0!
B24: Total Gain on Sale | H24: =H21+H22+H23 -> #DIV/0!
B25: Depreciation Recapture | H25: =-MIN(-H10,H24)*Assumptions!C47 -> #DIV/0!
B26: Capital Gains Tax | H26: =-MAX(H24+H10,0)*Assumptions!C46 -> #DIV/0!
B27: Total Tax on Sale | H27: =H25+H26 -> #DIV/0!
A29: UNLEVERED AFTER-TAX CASH FLOW
B30: Acquisition Cost | C30: ='Before-Tax DCF'!C24 -> 0
B31: Net Operating Income | D31: =D14 -> 0 | E31: =E14 -> 0 | F31: =F14 -> 0 | G31: =G14 -> 0 | H31: =H14 -> 0
B32: Less: Tax on Operations | D32: =D18 -> #VALUE! | E32: =E18 -> #VALUE! | F32: =F18 -> #VALUE! | G32: =G18 -> #VALUE! | H32: =H18 -> #VALUE!
B33: Net Sale Proceeds (before tax) | H33: ='Before-Tax DCF'!H26 -> #DIV/0!
B34: Less: Tax on Sale | H34: =H27 -> #DIV/0!
B35: Unlevered After-Tax CF | C35: =C30 -> 0 | D35: =D31+D32 -> #VALUE! | E35: =E31+E32 -> #VALUE! | F35: =F31+F32 -> #VALUE! | G35: =G31+G32 -> #VALUE! | H35: =H31+H32+H33+H34 -> #VALUE!
A37: UNLEVERED AFTER-TAX RETURN METRICS
B38: Unlevered After-Tax IRR | C38: =IRR(C35:H35) -> #VALUE!
B39: Unlevered After-Tax NPV | C39: =NPV(Assumptions!C52,D35:H35)+C35 -> #VALUE!
B40: Equity Multiple | C40: =SUM(D35:H35)/-C35 -> #VALUE!
A43: LEVERED AFTER-TAX CASH FLOW
B44: Equity Investment | C44: ='Before-Tax DCF'!C36 -> 0
B45: Before-Tax CF (Operations) | D45: ='Before-Tax DCF'!D39 -> 0 | E45: ='Before-Tax DCF'!E39 -> 0 | F45: ='Before-Tax DCF'!F39 -> 0 | G45: ='Before-Tax DCF'!G39 -> 0 | H45: ='Before-Tax DCF'!H39 -> 0
B46: Less: Tax on Operations | D46: =D18 -> #VALUE! | E46: =E18 -> #VALUE! | F46: =F18 -> #VALUE! | G46: =G18 -> #VALUE! | H46: =H18 -> #VALUE!
B47: Net Sale Proceeds (after payoff) | H47: ='Before-Tax DCF'!H40 -> #DIV/0!
B48: Less: Tax on Sale | H48: =H27 -> #DIV/0!
B49: Levered After-Tax CF | C49: =C44 -> 0 | D49: =D45+D46 -> #VALUE! | E49: =E45+E46 -> #VALUE! | F49: =F45+F46 -> #VALUE! | G49: =G45+G46 -> #VALUE! | H49: =H45+H46+H47+H48 -> #VALUE!
...

Sheet Dashboard
C1: StratiqAI | 5-Year DCF Model
A2: Investment Summary Dashboard
A5: PROPERTY OVERVIEW
B6: Property: | C6: =Assumptions!C6 -> 0 | E6: Location: | F6: =Assumptions!C8 -> 0
B7: Type: | C7: =Assumptions!C7 -> 0 | E7: Net Rentable SF: | F7: =Assumptions!C9 -> 0
B8: Purchase Price: | C8: =Assumptions!C10 -> 0 | E8: Price / SF: | F8: =Assumptions!C11 -> 0
B9: Total Investment: | C9: =Assumptions!C10*(1+Assumptions!C12)+Assumptions!C13 -> 0 | E9: Equity Required: | F9: =Assumptions!C37 -> 0
B10: Loan Amount: | C10: =Assumptions!C32 -> 0 | E10: LTV: | F10: =Assumptions!C31 -> 0
B11: Interest Rate: | C11: =Assumptions!C33 -> 0 | E11: Debt Service: | F11: =Assumptions!C36 -> 0
A13: RETURN METRICS COMPARISON
B14: Metric | C14: Unlevered | D14: Levered | E14: Unlevered | F14: Levered
C15: Before-Tax | D15: Before-Tax | E15: After-Tax | F15: After-Tax
B16: IRR | C16: ='Before-Tax DCF'!C30 -> #DIV/0! | D16: ='Before-Tax DCF'!C44 -> #DIV/0! | E16: ='After-Tax DCF'!C38 -> #VALUE! | F16: ='After-Tax DCF'!C52 -> #VALUE!
B17: NPV | C17: ='Before-Tax DCF'!C31 -> #DIV/0! | D17: ='Before-Tax DCF'!C45 -> #DIV/0! | E17: ='After-Tax DCF'!C39 -> #VALUE! | F17: ='After-Tax DCF'!C53 -> #VALUE!
B18: Equity Multiple | C18: ='Before-Tax DCF'!C32 -> #DIV/0! | D18: ='Before-Tax DCF'!C46 -> #DIV/0! | E18: ='After-Tax DCF'!C40 -> #VALUE! | F18: ='After-Tax DCF'!C54 -> #VALUE!
B19: Cash-on-Cash (Year 1) | C19: n/a | D19: ='Before-Tax DCF'!C47 -> #DIV/0! | E19: n/a | F19: ='After-Tax DCF'!C55 -> #VALUE!
A21: NET OPERATING INCOME SUMMARY
B22: ($) | C22: Year 1 | D22: Year 2 | E22: Year 3 | F22: Year 4 | G22: Year 5
B23: Net Operating Income | C23: ='Before-Tax DCF'!D21 -> 0 | D23: ='Before-Tax DCF'!E21 -> 0 | E23: ='Before-Tax DCF'!F21 -> 0 | F23: ='Before-Tax DCF'!G21 -> 0 | G23: ='Before-Tax DCF'!H21 -> 0
B24: NOI Growth (%) | C24: — | D24: =(D23-C23)/C23 -> #DIV/0! | E24: =(E23-D23)/D23 -> #DIV/0! | F24: =(F23-E23)/E23 -> #DIV/0! | G24: =(G23-F23)/F23 -> #DIV/0!
B25: Implied Cap Rate | C25: =C23/Assumptions!C10 -> #DIV/0! | D25: =D23/Assumptions!C10 -> #DIV/0! | E25: =E23/Assumptions!C10 -> #DIV/0! | F25: =F23/Assumptions!C10 -> #DIV/0! | G25: =G23/Assumptions!C10 -> #DIV/0!
B26: Debt Service Coverage Ratio | C26: =C23/Assumptions!C36 -> #DIV/0! | D26: =D23/Assumptions!C36 -> #DIV/0! | E26: =E23/Assumptions!C36 -> #DIV/0! | F26: =F23/Assumptions!C36 -> #DIV/0! | G26: =G23/Assumptions!C36 -> #DIV/0!
A28: EXIT / REVERSION ANALYSIS
B29: Exit Cap Rate | C29: =Assumptions!C40 -> 0
B30: Gross Sale Price (Year 6) | C30: =Assumptions!C42/Assumptions!C40 -> #DIV/0!
B31: Net Sale Proceeds (BT) | C31: ='Before-Tax DCF'!H26 -> #DIV/0!
B32: Total Tax on Sale | C32: ='After-Tax DCF'!H27 -> #DIV/0!
B33: Net Sale Proceeds (AT) | C33: =C31+C32 -> #DIV/0!
A35: KEY ASSUMPTIONS RECAP
B36: Discount Rate (Unlevered) | C36: =Assumptions!C52 -> 0
B37: Discount Rate (Levered) | C37: =Assumptions!C53 -> 0
B38: Ordinary Tax Rate | C38: =Assumptions!C45 -> 0
B39: Capital Gains Tax Rate | C39: =Assumptions!C46 -> 0
B40: Depreciation Recapture Rate | C40: =Assumptions!C47 -> 0
